Workbook

Sheet Instructions
A1: 5G NR COVERAGE RADIUS vs SNR CALCULATOR (DL & UL)
A3: OVERVIEW:
A4: This Excel workbook calculates the coverage radius (km) as a function of required SNR (dB) for both Downlink (BS→UE) and Uplink (UE→BS) directions using the TR 38.901 UMa LOS path-loss model with breakpoint.
A6: HOW TO USE:
A7: 1. Go to the 'Parameters & Formulas' sheet.
A8: 2. Edit the BLUE cells (editable parameters) in column B to match your scenario:
A9: - DOWNLINK: BS transmit power, BS antenna gain, BS cable losses, UE antenna gain, UE noise figure, penetration loss
A10: - UPLINK: UE transmit power, UE antenna gain, BS antenna gain, BS noise figure, BS cable losses
A11: - Common: Number of subcarriers, margins (fading, interference)
A12: - Path-loss model parameters (frequency, BS/UE heights)
A13: - MCS SNR thresholds (approximate, adjust as needed)
A14: 3. GREEN cells show calculated/derived values (formulas; do not edit directly).
... A52: Generated by: generate_radius_snr_excel_with_chart.py

Sheet Parameters & Formulas
A1: 5G NR Coverage Radius vs Required SNR Calculator (DL & UL)
A3: DOWNLINK (BS → UE) - TRANSMITTER PARAMETERS
A4: BS transmit power (dBm) | B4: 46 | C4: tx_power_dl | D4: P_BS
A5: BS antenna gain (dBi) | B5: 18 | C5: tx_gain_dl | D5: G_BS
A6: BS cable/connector losses (dB) | B6: 2.5 | C6: cable_loss_dl | D6: L_cable_BS
A7: Number of subcarriers | B7: 600 | C7: n_subcarriers | D7: D_sub (10 MHz BW)
A9: DOWNLINK (BS → UE) - RECEIVER PARAMETERS
A10: UE antenna gain (dBi) | B10: 0 | C10: rx_gain_dl | D10: G_UE
A11: UE noise figure (dB) | B11: 7 | C11: noise_figure_dl | D11: NF_UE
A12: Penetration loss (dB) | B12: 18 | C12: penetration_loss | D12: L_penetration
A13: Thermal noise density (dBm/Hz) | B13: -173.8 | C13: noise_density | D13: kT_0
A14: Subcarrier bandwidth (Hz) | B14: 15000 | C14: subcarrier_bw | D14: 15 kHz SCS
A16: MARGINS
A17: Fading margin (dB) | B17: 5 | C17: fading_margin | D17: M_f
A18: Interference degradation margin (dB) | B18: 2 | C18: interference_margin | D18: M_I
A20: PATH LOSS MODEL (TR 38.901 UMa LOS)
A21: Carrier frequency (GHz) | B21: 3.5 | C21: fc_ghz | D21: f_c
A22: Base station height (m) | B22: 30 | C22: h_bs | D22: h_BS
A23: UE height (m) | B23: 1.5 | C23: h_ut | D23: h_UT
A24: Speed of light (m/s) | B24: 300000000 | C24: c | D24: c
A26: DOWNLINK - CALCULATED / DERIVED VALUES
A27: DL EiRP (dBm) | B27: =B4+B5-B6 | C27: eirp_dl | D27: =P_BS + G_BS - L_cable_BS
A28: DL Per-subcarrier power (dBm) | B28: =B27-10*LOG10(B7) | C28: p_sub_dl | D28: =EiRP - 10·log10(D_sub)
A29: Noise power per subcarrier (dBm) | B29: =B13+10*LOG10(B14) | C29: noise_power | D29: =kT_0 + 10·log10(W)
A30: DL Total gains (dB) | B30: =B10 | C30: total_gains_dl | D30: =G_UE
A31: DL Total losses (dB) | B31: =B11+B12 | C31: total_losses_dl | D31: =NF_UE + L_penetration
A32: DL Effective power per subcarrier (dBm) | B32: =B28+B30-B31 | C32: T_eff_dl | D32: =P_sub + G_total - L_total
A33: Wavelength (m) | B33: =B24/(B21*1e9) | C33: lambda | D33: =c / (f_c × 10⁹)
A34: Breakpoint distance d_bp (m) | B34: =4*B22*B23/B33 | C34: d_bp | D34: =4·h_BS·h_UT / λ
A35: PL constant C (dB) | B35: =32.4+20*LOG10(B21) | C35: C_PL | D35: =32.4 + 20·log10(f_c) [f_c in GHz]
A36: PL at breakpoint (dB) | B36: =B35+20*LOG10(B34) | C36: PL_bp | D36: =C + 20·log10(d_bp)
A38: UPLINK (UE → BS) - TRANSMITTER PARAMETERS
A39: UE transmit power (dBm) | B39: 23 | C39: tx_power_ul | D39: P_UE (Class 3)
A40: UE antenna gain (dBi) | B40: 0 | C40: tx_gain_ul | D40: G_UE
A41: UE cable/connector losses (dB) | B41: 0 | C41: cable_loss_ul | D41: L_cable_UE
A43: UPLINK (UE → BS) - RECEIVER PARAMETERS
A44: BS antenna gain (dBi) | B44: 18 | C44: rx_gain_ul | D44: G_BS
A45: BS noise figure (dB) | B45: 3 | C45: noise_figure_ul | D45: NF_BS
A46: BS cable/connector losses (dB) | B46: 2.5 | C46: cable_loss_rx_ul | D46: L_cable_BS_RX
A48: UPLINK - CALCULATED / DERIVED VALUES
...

Sheet DL SNR vs Radius
A1: Required SNR (dB) | B1: DL L_max (dB) | C1: DL Radius (m) | D1: DL Radius (km) | E1: Formula Used
A2: 32 | B2: ='Parameters & Formulas'!$B$32-(A2+'Parameters & Formulas'!$B$29+'Parameters & Formulas'!$B$17+'Parameters & Formulas'!$B$18) | C2: =IF(B2<='Parameters & Formulas'!$B$36,POWER(10,(B2-'Parameters & Formulas'!$B$35)/20),POWER(10,(B2-'Parameters & Formulas'!$B$35+20*LOG10('Parameters & Formulas'!$B$34))/40)) | D2: =C2/1000 | E2: =IF(B2<='Parameters & Formulas'!$B$36,"Pre-breakpoint (20 log)","Post-breakpoint (40 log)")
A3: 31.828643 | B3: ='Parameters & Formulas'!$B$32-(A3+'Parameters & Formulas'!$B$29+'Parameters & Formulas'!$B$17+'Parameters & Formulas'!$B$18) | C3: =IF(B3<='Parameters & Formulas'!$B$36,POWER(10,(B3-'Parameters & Formulas'!$B$35)/20),POWER(10,(B3-'Parameters & Formulas'!$B$35+20*LOG10('Parameters & Formulas'!$B$34))/40)) | D3: =C3/1000 | E3: =IF(B3<='Parameters & Formulas'!$B$36,"Pre-breakpoint (20 log)","Post-breakpoint (40 log)")
A4: 31.657286 | B4: ='Parameters & Formulas'!$B$32-(A4+'Parameters & Formulas'!$B$29+'Parameters & Formulas'!$B$17+'Parameters & Formulas'!$B$18) | C4: =IF(B4<='Parameters & Formulas'!$B$36,POWER(10,(B4-'Parameters & Formulas'!$B$35)/20),POWER(10,(B4-'Parameters & Formulas'!$B$35+20*LOG10('Parameters & Formulas'!$B$34))/40)) | D4: =C4/1000 | E4: =IF(B4<='Parameters & Formulas'!$B$36,"Pre-breakpoint (20 log)","Post-breakpoint (40 log)")
A5: 31.48593 | B5: ='Parameters & Formulas'!$B$32-(A5+'Parameters & Formulas'!$B$29+'Parameters & Formulas'!$B$17+'Parameters & Formulas'!$B$18) | C5: =IF(B5<='Parameters & Formulas'!$B$36,POWER(10,(B5-'Parameters & Formulas'!$B$35)/20),POWER(10,(B5-'Parameters & Formulas'!$B$35+20*LOG10('Parameters & Formulas'!$B$34))/40)) | D5: =C5/1000 | E5: =IF(B5<='Parameters & Formulas'!$B$36,"Pre-breakpoint (20 log)","Post-breakpoint (40 log)")
A6: 31.314573 | B6: ='Parameters & Formulas'!$B$32-(A6+'Parameters & Formulas'!$B$29+'Parameters & Formulas'!$B$17+'Parameters & Formulas'!$B$18) | C6: =IF(B6<='Parameters & Formulas'!$B$36,POWER(10,(B6-'Parameters & Formulas'!$B$35)/20),POWER(10,(B6-'Parameters & Formulas'!$B$35+20*LOG10('Parameters & Formulas'!$B$34))/40)) | D6: =C6/1000 | E6: =IF(B6<='Parameters & Formulas'!$B$36,"Pre-breakpoint (20 log)","Post-breakpoint (40 log)")
A7: 31.143216 | B7: ='Parameters & Formulas'!$B$32-(A7+'Parameters & Formulas'!$B$29+'Parameters & Formulas'!$B$17+'Parameters & Formulas'!$B$18) | C7: =IF(B7<='Parameters & Formulas'!$B$36,POWER(10,(B7-'Parameters & Formulas'!$B$35)/20),POWER(10,(B7-'Parameters & Formulas'!$B$35+20*LOG10('Parameters & Formulas'!$B$34))/40)) | D7: =C7/1000 | E7: =IF(B7<='Parameters & Formulas'!$B$36,"Pre-breakpoint (20 log)","Post-breakpoint (40 log)")
A8: 30.971859 | B8: ='Parameters & Formulas'!$B$32-(A8+'Parameters & Formulas'!$B$29+'Parameters & Formulas'!$B$17+'Parameters & Formulas'!$B$18) | C8: =IF(B8<='Parameters & Formulas'!$B$36,POWER(10,(B8-'Parameters & Formulas'!$B$35)/20),POWER(10,(B8-'Parameters & Formulas'!$B$35+20*LOG10('Parameters & Formulas'!$B$34))/40)) | D8: =C8/1000 | E8: =IF(B8<='Parameters & Formulas'!$B$36,"Pre-breakpoint (20 log)","Post-breakpoint (40 log)")
A9: 30.800503 | B9: ='Parameters & Formulas'!$B$32-(A9+'Parameters & Formulas'!$B$29+'Parameters & Formulas'!$B$17+'Parameters & Formulas'!$B$18) | C9: =IF(B9<='Parameters & Formulas'!$B$36,POWER(10,(B9-'Parameters & Formulas'!$B$35)/20),POWER(10,(B9-'Parameters & Formulas'!$B$35+20*LOG10('Parameters & Formulas'!$B$34))/40)) | D9: =C9/1000 | E9: =IF(B9<='Parameters & Formulas'!$B$36,"Pre-breakpoint (20 log)","Post-breakpoint (40 log)")
A10: 30.629146 | B10: ='Parameters & Formulas'!$B$32-(A10+'Parameters & Formulas'!$B$29+'Parameters & Formulas'!$B$17+'Parameters & Formulas'!$B$18) | C10: =IF(B10<='Parameters & Formulas'!$B$36,POWER(10,(B10-'Parameters & Formulas'!$B$35)/20),POWER(10,(B10-'Parameters & Formulas'!$B$35+20*LOG10('Parameters & Formulas'!$B$34))/40)) | D10: =C10/1000 | E10: =IF(B10<='Parameters & Formulas'!$B$36,"Pre-breakpoint (20 log)","Post-breakpoint (40 log)")
A11: 30.457789 | B11: ='Parameters & Formulas'!$B$32-(A11+'Parameters & Formulas'!$B$29+'Parameters & Formulas'!$B$17+'Parameters & Formulas'!$B$18) | C11: =IF(B11<='Parameters & Formulas'!$B$36,POWER(10,(B11-'Parameters & Formulas'!$B$35)/20),POWER(10,(B11-'Parameters & Formulas'!$B$35+20*LOG10('Parameters & Formulas'!$B$34))/40)) | D11: =C11/1000 | E11: =IF(B11<='Parameters & Formulas'!$B$36,"Pre-breakpoint (20 log)","Post-breakpoint (40 log)")
A12: 30.286432 | B12: ='Parameters & Formulas'!$B$32-(A12+'Parameters & Formulas'!$B$29+'Parameters & Formulas'!$B$17+'Parameters & Formulas'!$B$18) | C12: =IF(B12<='Parameters & Formulas'!$B$36,POWER(10,(B12-'Parameters & Formulas'!$B$35)/20),POWER(10,(B12-'Parameters & Formulas'!$B$35+20*LOG10('Parameters & Formulas'!$B$34))/40)) | D12: =C12/1000 | E12: =IF(B12<='Parameters & Formulas'!$B$36,"Pre-breakpoint (20 log)","Post-breakpoint (40 log)")
A13: 30.115075 | B13: ='Parameters & Formulas'!$B$32-(A13+'Parameters & Formulas'!$B$29+'Parameters & Formulas'!$B$17+'Parameters & Formulas'!$B$18) | C13: =IF(B13<='Parameters & Formulas'!$B$36,POWER(10,(B13-'Parameters & Formulas'!$B$35)/20),POWER(10,(B13-'Parameters & Formulas'!$B$35+20*LOG10('Parameters & Formulas'!$B$34))/40)) | D13: =C13/1000 | E13: =IF(B13<='Parameters & Formulas'!$B$36,"Pre-breakpoint (20 log)","Post-breakpoint (40 log)")
... A201: -2.1 | B201: ='Parameters & Formulas'!$B$32-(A201+'Parameters & Formulas'!$B$29+'Parameters & Formulas'!$B$17+'Parameters & Formulas'!$B$18) | C201: =IF(B201<='Parameters & Formulas'!$B$36,POWER(10,(B201-'Parameters & Formulas'!$B$35)/20),POWER(10,(B201-'Parameters & Formulas'!$B$35+20*LOG10('Parameters & Formulas'!$B$34))/40)) | D201: =C201/1000 | E201: =IF(B201<='Parameters & Formulas'!$B$36,"Pre-breakpoint (20 log)","Post-breakpoint (40 log)")

Sheet UL SNR vs Radius
A1: Required SNR (dB) | B1: UL L_max (dB) | C1: UL Radius (m) | D1: UL Radius (km) | E1: Formula Used
A2: 32 | B2: ='Parameters & Formulas'!$B$53-(A2+'Parameters & Formulas'!$B$29+'Parameters & Formulas'!$B$17+'Parameters & Formulas'!$B$18) | C2: =IF(B2<='Parameters & Formulas'!$B$36,POWER(10,(B2-'Parameters & Formulas'!$B$35)/20),POWER(10,(B2-'Parameters & Formulas'!$B$35+20*LOG10('Parameters & Formulas'!$B$34))/40)) | D2: =C2/1000 | E2: =IF(B2<='Parameters & Formulas'!$B$36,"Pre-breakpoint (20 log)","Post-breakpoint (40 log)")
A3: 31.828643 | B3: ='Parameters & Formulas'!$B$53-(A3+'Parameters & Formulas'!$B$29+'Parameters & Formulas'!$B$17+'Parameters & Formulas'!$B$18) | C3: =IF(B3<='Parameters & Formulas'!$B$36,POWER(10,(B3-'Parameters & Formulas'!$B$35)/20),POWER(10,(B3-'Parameters & Formulas'!$B$35+20*LOG10('Parameters & Formulas'!$B$34))/40)) | D3: =C3/1000 | E3: =IF(B3<='Parameters & Formulas'!$B$36,"Pre-breakpoint (20 log)","Post-breakpoint (40 log)")
A4: 31.657286 | B4: ='Parameters & Formulas'!$B$53-(A4+'Parameters & Formulas'!$B$29+'Parameters & Formulas'!$B$17+'Parameters & Formulas'!$B$18) | C4: =IF(B4<='Parameters & Formulas'!$B$36,POWER(10,(B4-'Parameters & Formulas'!$B$35)/20),POWER(10,(B4-'Parameters & Formulas'!$B$35+20*LOG10('Parameters & Formulas'!$B$34))/40)) | D4: =C4/1000 | E4: =IF(B4<='Parameters & Formulas'!$B$36,"Pre-breakpoint (20 log)","Post-breakpoint (40 log)")
A5: 31.48593 | B5: ='Parameters & Formulas'!$B$53-(A5+'Parameters & Formulas'!$B$29+'Parameters & Formulas'!$B$17+'Parameters & Formulas'!$B$18) | C5: =IF(B5<='Parameters & Formulas'!$B$36,POWER(10,(B5-'Parameters & Formulas'!$B$35)/20),POWER(10,(B5-'Parameters & Formulas'!$B$35+20*LOG10('Parameters & Formulas'!$B$34))/40)) | D5: =C5/1000 | E5: =IF(B5<='Parameters & Formulas'!$B$36,"Pre-breakpoint (20 log)","Post-breakpoint (40 log)")
A6: 31.314573 | B6: ='Parameters & Formulas'!$B$53-(A6+'Parameters & Formulas'!$B$29+'Parameters & Formulas'!$B$17+'Parameters & Formulas'!$B$18) | C6: =IF(B6<='Parameters & Formulas'!$B$36,POWER(10,(B6-'Parameters & Formulas'!$B$35)/20),POWER(10,(B6-'Parameters & Formulas'!$B$35+20*LOG10('Parameters & Formulas'!$B$34))/40)) | D6: =C6/1000 | E6: =IF(B6<='Parameters & Formulas'!$B$36,"Pre-breakpoint (20 log)","Post-breakpoint (40 log)")
A7: 31.143216 | B7: ='Parameters & Formulas'!$B$53-(A7+'Parameters & Formulas'!$B$29+'Parameters & Formulas'!$B$17+'Parameters & Formulas'!$B$18) | C7: =IF(B7<='Parameters & Formulas'!$B$36,POWER(10,(B7-'Parameters & Formulas'!$B$35)/20),POWER(10,(B7-'Parameters & Formulas'!$B$35+20*LOG10('Parameters & Formulas'!$B$34))/40)) | D7: =C7/1000 | E7: =IF(B7<='Parameters & Formulas'!$B$36,"Pre-breakpoint (20 log)","Post-breakpoint (40 log)")
A8: 30.971859 | B8: ='Parameters & Formulas'!$B$53-(A8+'Parameters & Formulas'!$B$29+'Parameters & Formulas'!$B$17+'Parameters & Formulas'!$B$18) | C8: =IF(B8<='Parameters & Formulas'!$B$36,POWER(10,(B8-'Parameters & Formulas'!$B$35)/20),POWER(10,(B8-'Parameters & Formulas'!$B$35+20*LOG10('Parameters & Formulas'!$B$34))/40)) | D8: =C8/1000 | E8: =IF(B8<='Parameters & Formulas'!$B$36,"Pre-breakpoint (20 log)","Post-breakpoint (40 log)")
A9: 30.800503 | B9: ='Parameters & Formulas'!$B$53-(A9+'Parameters & Formulas'!$B$29+'Parameters & Formulas'!$B$17+'Parameters & Formulas'!$B$18) | C9: =IF(B9<='Parameters & Formulas'!$B$36,POWER(10,(B9-'Parameters & Formulas'!$B$35)/20),POWER(10,(B9-'Parameters & Formulas'!$B$35+20*LOG10('Parameters & Formulas'!$B$34))/40)) | D9: =C9/1000 | E9: =IF(B9<='Parameters & Formulas'!$B$36,"Pre-breakpoint (20 log)","Post-breakpoint (40 log)")
A10: 30.629146 | B10: ='Parameters & Formulas'!$B$53-(A10+'Parameters & Formulas'!$B$29+'Parameters & Formulas'!$B$17+'Parameters & Formulas'!$B$18) | C10: =IF(B10<='Parameters & Formulas'!$B$36,POWER(10,(B10-'Parameters & Formulas'!$B$35)/20),POWER(10,(B10-'Parameters & Formulas'!$B$35+20*LOG10('Parameters & Formulas'!$B$34))/40)) | D10: =C10/1000 | E10: =IF(B10<='Parameters & Formulas'!$B$36,"Pre-breakpoint (20 log)","Post-breakpoint (40 log)")
A11: 30.457789 | B11: ='Parameters & Formulas'!$B$53-(A11+'Parameters & Formulas'!$B$29+'Parameters & Formulas'!$B$17+'Parameters & Formulas'!$B$18) | C11: =IF(B11<='Parameters & Formulas'!$B$36,POWER(10,(B11-'Parameters & Formulas'!$B$35)/20),POWER(10,(B11-'Parameters & Formulas'!$B$35+20*LOG10('Parameters & Formulas'!$B$34))/40)) | D11: =C11/1000 | E11: =IF(B11<='Parameters & Formulas'!$B$36,"Pre-breakpoint (20 log)","Post-breakpoint (40 log)")
A12: 30.286432 | B12: ='Parameters & Formulas'!$B$53-(A12+'Parameters & Formulas'!$B$29+'Parameters & Formulas'!$B$17+'Parameters & Formulas'!$B$18) | C12: =IF(B12<='Parameters & Formulas'!$B$36,POWER(10,(B12-'Parameters & Formulas'!$B$35)/20),POWER(10,(B12-'Parameters & Formulas'!$B$35+20*LOG10('Parameters & Formulas'!$B$34))/40)) | D12: =C12/1000 | E12: =IF(B12<='Parameters & Formulas'!$B$36,"Pre-breakpoint (20 log)","Post-breakpoint (40 log)")
A13: 30.115075 | B13: ='Parameters & Formulas'!$B$53-(A13+'Parameters & Formulas'!$B$29+'Parameters & Formulas'!$B$17+'Parameters & Formulas'!$B$18) | C13: =IF(B13<='Parameters & Formulas'!$B$36,POWER(10,(B13-'Parameters & Formulas'!$B$35)/20),POWER(10,(B13-'Parameters & Formulas'!$B$35+20*LOG10('Parameters & Formulas'!$B$34))/40)) | D13: =C13/1000 | E13: =IF(B13<='Parameters & Formulas'!$B$36,"Pre-breakpoint (20 log)","Post-breakpoint (40 log)")
... A201: -2.1 | B201: ='Parameters & Formulas'!$B$53-(A201+'Parameters & Formulas'!$B$29+'Parameters & Formulas'!$B$17+'Parameters & Formulas'!$B$18) | C201: =IF(B201<='Parameters & Formulas'!$B$36,POWER(10,(B201-'Parameters & Formulas'!$B$35)/20),POWER(10,(B201-'Parameters & Formulas'!$B$35+20*LOG10('Parameters & Formulas'!$B$34))/40)) | D201: =C201/1000 | E201: =IF(B201<='Parameters & Formulas'!$B$36,"Pre-breakpoint (20 log)","Post-breakpoint (40 log)")

Sheet DL MCS Markers
A1: MCS | B1: SNR (dB) | C1: DL L_max (dB) | D1: DL Radius (m) | E1: DL Radius (km)
A2: 256-QAM | B2: ='Parameters & Formulas'!$B$56 | C2: ='Parameters & Formulas'!$B$32-(B2+'Parameters & Formulas'!$B$29+'Parameters & Formulas'!$B$17+'Parameters & Formulas'!$B$18) | D2: =IF(C2<='Parameters & Formulas'!$B$36,POWER(10,(C2-'Parameters & Formulas'!$B$35)/20),POWER(10,(C2-'Parameters & Formulas'!$B$35+20*LOG10('Parameters & Formulas'!$B$34))/40)) | E2: =D2/1000
A3: 64-QAM | B3: ='Parameters & Formulas'!$B$57 | C3: ='Parameters & Formulas'!$B$32-(B3+'Parameters & Formulas'!$B$29+'Parameters & Formulas'!$B$17+'Parameters & Formulas'!$B$18) | D3: =IF(C3<='Parameters & Formulas'!$B$36,POWER(10,(C3-'Parameters & Formulas'!$B$35)/20),POWER(10,(C3-'Parameters & Formulas'!$B$35+20*LOG10('Parameters & Formulas'!$B$34))/40)) | E3: =D3/1000
A4: 16-QAM | B4: ='Parameters & Formulas'!$B$58 | C4: ='Parameters & Formulas'!$B$32-(B4+'Parameters & Formulas'!$B$29+'Parameters & Formulas'!$B$17+'Parameters & Formulas'!$B$18) | D4: =IF(C4<='Parameters & Formulas'!$B$36,POWER(10,(C4-'Parameters & Formulas'!$B$35)/20),POWER(10,(C4-'Parameters & Formulas'!$B$35+20*LOG10('Parameters & Formulas'!$B$34))/40)) | E4: =D4/1000
A5: QPSK | B5: ='Parameters & Formulas'!$B$59 | C5: ='Parameters & Formulas'!$B$32-(B5+'Parameters & Formulas'!$B$29+'Parameters & Formulas'!$B$17+'Parameters & Formulas'!$B$18) | D5: =IF(C5<='Parameters & Formulas'!$B$36,POWER(10,(C5-'Parameters & Formulas'!$B$35)/20),POWER(10,(C5-'Parameters & Formulas'!$B$35+20*LOG10('Parameters & Formulas'!$B$34))/40)) | E5: =D5/1000

Sheet UL MCS Markers
A1: MCS | B1: SNR (dB) | C1: UL L_max (dB) | D1: UL Radius (m) | E1: UL Radius (km)
A2: 256-QAM | B2: ='Parameters & Formulas'!$B$56 | C2: ='Parameters & Formulas'!$B$53-(B2+'Parameters & Formulas'!$B$29+'Parameters & Formulas'!$B$17+'Parameters & Formulas'!$B$18) | D2: =IF(C2<='Parameters & Formulas'!$B$36,POWER(10,(C2-'Parameters & Formulas'!$B$35)/20),POWER(10,(C2-'Parameters & Formulas'!$B$35+20*LOG10('Parameters & Formulas'!$B$34))/40)) | E2: =D2/1000
A3: 64-QAM | B3: ='Parameters & Formulas'!$B$57 | C3: ='Parameters & Formulas'!$B$53-(B3+'Parameters & Formulas'!$B$29+'Parameters & Formulas'!$B$17+'Parameters & Formulas'!$B$18) | D3: =IF(C3<='Parameters & Formulas'!$B$36,POWER(10,(C3-'Parameters & Formulas'!$B$35)/20),POWER(10,(C3-'Parameters & Formulas'!$B$35+20*LOG10('Parameters & Formulas'!$B$34))/40)) | E3: =D3/1000
A4: 16-QAM | B4: ='Parameters & Formulas'!$B$58 | C4: ='Parameters & Formulas'!$B$53-(B4+'Parameters & Formulas'!$B$29+'Parameters & Formulas'!$B$17+'Parameters & Formulas'!$B$18) | D4: =IF(C4<='Parameters & Formulas'!$B$36,POWER(10,(C4-'Parameters & Formulas'!$B$35)/20),POWER(10,(C4-'Parameters & Formulas'!$B$35+20*LOG10('Parameters & Formulas'!$B$34))/40)) | E4: =D4/1000
A5: QPSK | B5: ='Parameters & Formulas'!$B$59 | C5: ='Parameters & Formulas'!$B$53-(B5+'Parameters & Formulas'!$B$29+'Parameters & Formulas'!$B$17+'Parameters & Formulas'!$B$18) | D5: =IF(C5<='Parameters & Formulas'!$B$36,POWER(10,(C5-'Parameters & Formulas'!$B$35)/20),POWER(10,(C5-'Parameters & Formulas'!$B$35+20*LOG10('Parameters & Formulas'!$B$34))/40)) | E5: =D5/1000

Sheet DL Chart

Sheet UL Chart
